<mujocoinclude>

        <body pos="0 0 0">    
            <geom name="piping1" size="0.015 0.05" pos="0.05 0 0" type="cylinder" euler="0 1.57 0" contype="0" conaffinity="0"  rgba="0.8 0.8 0.8 1"/>
            <geom name="piping2" size="0.015 0.1" pos="0.05 0 0.1" type="capsule"   rgba="0.8 0.8 0.8 1"/>
            <geom name="piping3" size="0.015 0.08" pos="-0.03 0 0.2" type="capsule" euler="0 1.57 0"   rgba="0.8 0.8 0.8 1"/>
            <geom name="piping4" size="0.015 0.025" pos="-0.11 0 0.175" type="capsule"   rgba="0.8 0.8 0.8 1"/>
            <geom name="faucet" size="0.02 0.01" pos="-0.11 0 0.14" type="cylinder"   rgba="0.8 0.8 0.8 1"/>
            <geom name="box_stand" size="0.06 0.05 0.1" pos="0.15 0 -0.05" type="box"   rgba="0.8 0.8 0.8 1"/>

                <body> 
                    <geom name="tcirc" size="0.04 0.012" quat="0.707388 0 0.706825 0" type="cylinder"   rgba="0.8 0.8 0.8 1"/>
                    <geom name="th1" size="0.012 0.06" pos="0 0 0" type="capsule" euler="0 0 0"   rgba="0.8 0.8 0.8 1 "/>
                    <geom name="th2" size="0.012 0.06" pos="0 0 0" type="capsule" euler="1.57 0 0"   rgba="0.8 0.8 0.8 1 "/>
                    <joint name="tapj" type="hinge" pos="0 0 0" damping="0.5" axis="1 0 0"/>
                </body>
        </body>  

</mujocoinclude>