<mujocoinclude>

    <body>    
        <geom name="door_case" size="0.03 0.2 0.2" pos="-0.01 0.15 0" type="box" condim="4" rgba="0.8 0.8 0.8 1"/>

            <body>
                <geom name="d_door" size="0.01 0.18 0.18" pos="-0.05 0.15 0" type="box" contype="0" conaffinity="0" condim="4" rgba="0.5 0.2 0.2 1"/>
                <geom name="dr_handle" size="0.07 0.01" pos="-0.11 0.3 0" type="cylinder" euler="0 1.57 0" condim="4" rgba="0.8 0.8 0.8 1"/>
                <geom name="dr_connect" size="0.01 0.025" pos="-0.075 0.3 0" type="cylinder" euler="0 1.57 0" condim="4" rgba="0.8 0.8 0.8 1"/> 
                <joint name="doorj" type="hinge" pos="0 0 0" axis="0 0 1"/>
            </body>    
    </body>        

</mujocoinclude>            