<mujocoinclude>

    <body>    
        <geom name="oven_body" size="0.15 0.2 0.2" pos="0.115 0.15 0" type="box" condim="4" rgba="0.8 0.8 0.8 1"/>

            <body>
                <geom name="d_oven" size="0.01 0.18 0.18" pos="-0.05 0.15 0" type="box" contype="0" conaffinity="0" condim="4" rgba="0.1 0.1 0.1 1"/>
                <geom name="ov_h1" size="0.01 0.05" pos="-0.1 0.3 0.1" type="capsule" euler="0 1.57 0" condim="4" rgba="0.8 0.8 0.8 1"/> 
                <geom name="ov_h2" size="0.01 0.1" pos="-0.15 0.3 0" type="capsule" euler="0 0 0" condim="4" rgba="0.8 0.8 0.8 1"/>
                <geom name="ov_h3" size="0.01 0.05" pos="-0.1 0.3 -0.1" type="capsule" euler="0 1.57 0" condim="4" rgba="0.8 0.8 0.8 1"/>
                <joint name="ovenj" type="hinge" pos="0 0 0" axis="0 0 1"/>
            </body>    
    </body>        

</mujocoinclude>            