<mujocoinclude>

             <geom name="arbody" size="0.05 0.15" quat="0.70788 0 0.706825 0" type="cylinder" condim="4" rgba="0.8 0.5 0.5 1"/>
             <geom name="front" size="0.05" pos="-0.15 0 0" type="sphere" condim="4" rgba="0.8 0.5 0.5 1"/>
             <geom name="tail" size="0.1  0.05 0.05" pos="0.15 0 0" type="ellipsoid" condim="4" rgba="0.8 0.5 0.5 1"/>
             <geom name="rudder" size="0.05 0.01" pos="0.21 0 0.04" type="cylinder" euler="1.57 0 0" condim="4" rgba="0.8 0.5 0.5 1"/>
             <geom name="wing" size="0.01 0.3 0.06" pos="0 0 0" type="ellipsoid" euler="0 1.57 0" condim="4" rgba="0.8 0.8 0.5 1"/>
             <geom name="atip" size="0.02" pos="-0.19 0 0" type="sphere" condim="4" rgba="0.4 0.3 0.3 1"/>
        <body euler="0.5 0 0">     
             <geom name="prop1" size="0.005 0.01 0.05" pos="-0.2 0.05 0" type="ellipsoid" euler="1.57 0 0" condim="4" rgba="0.8 0.8 0.5 1"/>
             <geom name="prop2" size="0.005 0.01 0.05" pos="-0.2 -0.05 0" type="ellipsoid" euler="1.57 0 0" condim="4" rgba="0.8 0.8 0.5 1"/>
             <joint name="propj" type="hinge" pos="-0.2 0 0" axis="1 0 0"/>
        </body>     

</mujocoinclude>             