<mujocoinclude>

    <body pos="0 0 0">  

        <body>   
            <geom name="scirc1" size="0.06 0.012" quat="0.707388 0 0.706825 0" type="cylinder" condim="4" rgba="0.8 0.8 0.8 1"/>
            <geom name="scirc2" size="0.05 0.012" pos="-0.005 0 0" type="cylinder" euler="0 1.57 0" condim="4" rgba="0.2 0.2 0.2 1"/>
            <geom name="ts1" size="0.012 0.1" pos="0 0 0" type="capsule" euler="0 0 0" condim="4" rgba="0.8 0.8 0.8 1 "/>
            <geom name="ts2" size="0.012 0.1" pos="0 0 0" type="capsule" euler="1.57 0 0" condim="4" rgba="0.8 0.8 0.8 1 "/>
            <geom name="ts3" size="0.012 0.1" pos="0 0 0" type="capsule" euler="0.785 0 0" condim="4" rgba="0.8 0.8 0.8 1 "/>
            <geom name="ts4" size="0.012 0.1" pos="0 0 0" type="capsule" euler="-0.785 0 0" condim="4" rgba="0.8 0.8 0.8 1 "/>
            <joint name="safej" type="hinge" pos="0 0 0" axis="1 0 0"/>
        </body>    
            <geom name="sconnect" size="0.015 0.05" pos="0.05 0 0" type="cylinder" contype="0" conaffinity="0" euler="0 1.57 0" condim="4" rgba="0.8 0.8 0.8 1"/>
            <geom name="safe_case" size="0.2 0.2 0.2" pos="0.25 0.15 0" type="box" condim="4" rgba="0.8 0.8 0.8 1"/>
            <geom name="safe_door" size="0.01 0.18 0.18" pos="0.05 0.15 0" type="box" condim="4" rgba="0.2 0.2 0.2 1"/>

    </body>        

</mujocoinclude>            